<?xml version="1.0" encoding="utf-8"?>

<robot
    name="binbot" xmlns:xacro="http://www.ros.org/wiki/xacro">

  <xacro:include filename="$(find binbot_description)/urdf/binbot.gazebo"/>


  <link name="base_link"></link>


 <joint name="joint_base" type="fixed">
    <parent link="base_link"/>
    <child link="chassis_link"/>
  </joint>
  <link
    name="chassis_link">
    <inertial>
      <origin
        xyz="0.000746112599556537 5.73870420864098E-05 0.0362024553881127"
        rpy="0 0 0" />
      <mass
        value="6.9713910509313" />
      <inertia
        ixx="0.160050269475172"
        ixy="0"
        ixz="0.0"
        iyy="0.167840131407414"
        iyz="0"
        izz="0.199929277805885" />
    </inertial>
    <visual>
      <origin
        xyz="0 0 0"
        rpy="0 0 0" />
      <geometry>
        <mesh
          filename="package://binbot_description/meshes/chassis_link.STL" />
      </geometry>
      <material
        name="AL">
        <color
          rgba="0.898039215686275 0.917647058823529 0.929411764705882 1" />
      </material>
    </visual>
    <collision>
      <origin
        xyz="0 0 0"
        rpy="0 0 0" />
      <geometry>
        <mesh
          filename="package://binbot_description/meshes/chassis_link.STL" />
      </geometry>
    </collision>
  </link>
  <link
    name="FRcastor_link">
    <inertial>
      <origin
        xyz="0 0 0"
        rpy="0 0 0" />
      <mass
        value="0.13444" />
      <inertia
        ixx="4.8343E-05"
        ixy="0"
        ixz="0"
        iyy="5.4779E-05"
        iyz="0"
        izz="5.0353E-05" />
    </inertial>
    <visual>
      <origin
        xyz="0 0 0"
        rpy="0 0 0" />
      <geometry>
        <mesh
          filename="package://binbot_description/meshes/FRcastor_link.STL" />
      </geometry>
      <material
        name="AL">
        <color
          rgba="0.75294 0.75294 0.75294 1" />
      </material>
    </visual>
    <collision>
      <origin
        xyz="0 0 0"
        rpy="0 0 0" />
      <geometry>
        <mesh
          filename="package://binbot_description/meshes/FRcastor_link.STL" />
      </geometry>
    </collision>
  </link>
  <joint
    name="FRcastor_joint"
    type="fixed">
    <origin
      xyz="0 0 0"
      rpy="0 0 0" />
    <parent
      link="chassis_link" />
    <child
      link="FRcastor_link" />
    <axis
      xyz="0 0 0" />
  </joint>
  <link
    name="FLcastor_link">
    <inertial>
      <origin
        xyz="0 0 0"
        rpy="0 0 0" />
      <mass
        value="0.13444" />
      <inertia
        ixx="4.8332E-05"
        ixy="0"
        ixz="0"
        iyy="5.479E-05"
        iyz="0"
        izz="5.0353E-05" />
    </inertial>
    <visual>
      <origin
        xyz="0 0 0"
        rpy="0 0 0" />
      <geometry>
        <mesh
          filename="package://binbot_description/meshes/FLcastor_link.STL" />
      </geometry>
      <material
        name="AL">
        <color
          rgba="0.75294 0.75294 0.75294 1" />
      </material>
    </visual>
    <collision>
      <origin
        xyz="0 0 0"
        rpy="0 0 0" />
      <geometry>
        <mesh
          filename="package://binbot_description/meshes/FLcastor_link.STL" />
      </geometry>
    </collision>
  </link>
  <joint
    name="FLcastor_joint"
    type="fixed">
    <origin
      xyz="0 0 0"
      rpy="0 0 0" />
    <parent
      link="chassis_link" />
    <child
      link="FLcastor_link" />
    <axis
      xyz="0 0 0" />
  </joint>
  <link
    name="BRcastor_link">
    <inertial>
      <origin
        xyz="0 0 0"
        rpy="0 0 0" />
      <mass
        value="0.13444" />
      <inertia
        ixx="4.8398E-05"
        ixy="0"
        ixz="0"
        iyy="5.4725E-05"
        iyz="0"
        izz="5.0353E-05" />
    </inertial>
    <visual>
      <origin
        xyz="0 0 0"
        rpy="0 0 0" />
      <geometry>
        <mesh
          filename="package://binbot_description/meshes/BRcastor_link.STL" />
      </geometry>
      <material
        name="AL">
        <color
          rgba="0.75294 0.75294 0.75294 1" />
      </material>
    </visual>
    <collision>
      <origin
        xyz="0 0 0"
        rpy="0 0 0" />
      <geometry>
        <mesh
          filename="package://binbot_description/meshes/BRcastor_link.STL" />
      </geometry>
    </collision>
  </link>
  <joint
    name="BRcastor_joint"
    type="fixed">
    <origin
      xyz="0 0 0"
      rpy="0 0 0" />
    <parent
      link="chassis_link" />
    <child
      link="BRcastor_link" />
    <axis
      xyz="0 0 0" />
  </joint>
  <link
    name="BLcastor_link">
    <inertial>
      <origin
        xyz="-0.230813994823497 0.117568268519039 -0.283501827258346"
        rpy="0 0 0" />
      <mass
        value="0.134438438452519" />
      <inertia
        ixx="4.83202156037859E-05"
        ixy="0"
        ixz="0"
        iyy="5.48024819135638E-05"
        iyz="0"
        izz="5.03528153762235E-05" />
    </inertial>
    <visual>
      <origin
        xyz="0 0 0"
        rpy="0 0 0" />
      <geometry>
        <mesh
          filename="package://binbot_description/meshes/BLcastor_link.STL" />
      </geometry>
      <material
        name="">
        <color
          rgba="0.752941176470588 0.752941176470588 0.752941176470588 1" />
      </material>
    </visual>
    <collision>
      <origin
        xyz="0 0 0"
        rpy="0 0 0" />
      <geometry>
        <mesh
          filename="package://binbot_description/meshes/BLcastor_link.STL" />
      </geometry>
    </collision>
  </link>
  <joint
    name="BLcastor_joint"
    type="fixed">
    <origin
      xyz="0 0 0"
      rpy="0 0 0" />
    <parent
      link="chassis_link" />
    <child
      link="BLcastor_link" />
    <axis
      xyz="0 0 0" />
  </joint>


  
  <link
    name="rwheel">
    <inertial>
      <origin
        xyz="0 0 0"
        rpy="0 0 0" />
      <mass
        value="0.19464" />
      <inertia
        ixx="0.00023936"
        ixy="0"
        ixz="0"
        iyy="0.00023937"
        iyz="0"
        izz="0.0004471" />
    </inertial>
    <visual>
      <origin
        xyz="0 0 0"
        rpy="0 0 0" />
      <geometry>
        <mesh
          filename="package://binbot_description/meshes/right_wheel.STL" />
      </geometry>
      <material
        name="AL">
        <color
          rgba="0.79216 0.81961 0.93333 1" />
      </material>
    </visual>
    <collision>
      <origin
        xyz="0 0 0"
        rpy="0 0 0" />
      <geometry>
        <mesh
          filename="package://binbot_description/meshes/right_wheel.STL" />
      </geometry>
    </collision>
  </link>
  <joint
    name="base_to_rwheel"
    type="continuous">
    <origin
      xyz="-0.005693 -0.21494 -0.25969"
      rpy="-1.5708 0 0" />
    <parent
      link="chassis_link" />
    <child
      link="rwheel" />
    <axis
      xyz="0 0 1" />
  </joint>




  <link
    name="lwheel">
   <inertial>
      <origin
        xyz="0 0 0"
        rpy="0 0 0" />
      <mass
        value="0.19464" />
      <inertia
        ixx="0.00023936"
        ixy="0"
        ixz="0"
        iyy="0.00023937"
        iyz="0"
        izz="0.0004471" />
    </inertial>
    <visual>
      <origin
        xyz="0 0 0"
        rpy="0 0 0" />
      <geometry>
        <mesh
          filename="package://binbot_description/meshes/left_wheel.STL" />
      </geometry>
      <material
        name="">
        <color
          rgba="1 1 1 1" />
      </material>
    </visual>
    <collision>
      <origin
        xyz="0 0 0"
        rpy="0 0 0" />
      <geometry>
        <mesh
          filename="package://binbot_description/meshes/left_wheel.STL" />
      </geometry>
    </collision>
  </link>
  <joint
    name="base_to_lwheel"
    type="continuous">
    <origin
      xyz="-0.005693 0.21506 -0.25969"
      rpy="-1.5708 0 -3.1416" />
    <parent
      link="chassis_link" />
    <child
      link="lwheel" />
    <axis
      xyz="0 0 -1" />
  </joint>

   <!--camera link-->

  <link name="camera">
      <inertial>
        <origin xyz="0.0 0.0 0.0" rpy="0.0 0.0 0.0"/>
        <mass value="0.1"/>
        <inertia ixx="1e-6" ixy="0.0" ixz="0.0" iyy="1e-6" iyz="0.0" izz="1e-6"/>
      </inertial>
      <visual name="">
        <origin xyz="0.0 0.0 0.0" rpy="0.0 0.0 0.0"/>
        <geometry>
          <box size="0.003 0.05 0.05"/>
        </geometry>
        
      </visual>
      <collision>
        <origin xyz="0.0 0.0 0.0" rpy="0.0 0.0 0.0"/>
        <geometry>
          <box size="0.003 0.05 0.05"/>
        </geometry>
      </collision>
      <gazebo reference="camera">
          <material>Gazebo/Green</material>
      </gazebo>
  </link>

  <joint name="camera_joint" type="fixed">
    <origin xyz="0.4 0.0 0.32" rpy="0.0 1.6 0.0"/>
    <parent link="chassis_link"/>
    <child link="camera"/>
    <axis xyz="1 0.0 0.0"/>
  </joint>


  <!--kinect_link-->
  <link name="camera_link">
      <inertial>
        <origin xyz="0.0 0.0 0.0" rpy="0.0 0.0 0.0"/>
        <mass value="0.1"/>
        <inertia ixx="1e-6" ixy="0.0" ixz="0.0" iyy="1e-6" iyz="0.0" izz="1e-6"/>
      </inertial>
      <visual name="">
        <origin xyz="0.0 0.0 0.0" rpy="0.0 0.0 0.0"/>
        <geometry>
          <mesh filename="package://binbot_description/meshes/kinect.dae"/>
        </geometry>
        <material name="white"/>
      </visual>
      <collision>
        <origin xyz="0.0 0.0 0.0" rpy="0.0 0.0 0.0"/>
        <geometry>
          <box size="0.05 0.05 0.05"/>
        </geometry>
      </collision>
  
         
      
  </link>

  <joint name="kinect_joint" type="fixed">
    <origin xyz="0.24 0.0 0.452" rpy="0.0 0.0 0.0"/>
    <parent link="chassis_link"/>
    <child link="camera_link"/>
    <axis xyz="0.0 1 0.0"/>
  </joint>


  <joint name="camera_optical_joint" type="fixed">
      <origin xyz="0 0 0" rpy="-1.5707 0 -1.5707"/>
      <parent link="camera_link"/>
      <child link="camera_depth_frame"/>
  </joint>

  <link name="camera_depth_frame">
  </link>

  <!--joint name="camera_optical_joint2" type="fixed">
    <origin xyz="0 0 0" rpy="-1.5707 0 -1.5707"/>
    <parent link="camera_depth_frame"/>
    <child link="camera_depth_optical_frame"/>
  </joint>

  <link name="camera_depth_optical_frame">
  </link-->

</robot>
